func f() {
    defer func() {
        if r := recover(); r != nil {
            fmt.Println("Recovered in f", r)
        }
    }()
    fmt.Println("Calling g.")
    g(0)
    fmt.Println("Returned normally from g.")
}

注意： 

如果defer捕获到了错误，这时候不会管返回值
